// Async Wrapper Function to handle errors
const asyncWrapper = (fn) => {
    return async (req, res, next) => {
        try {
            await fn(req, res, next);
        } catch (error) {
            return next(error)
            // res.status(400).json({ errName: error.name, errMsg: error.message })
        }
    }
}

module.exports = asyncWrapper;